Workbook

Sheet Guide
A1: US + Portugal Tax Planning Workbook (Tax Year 2026)
A2: Calculator + reference for a US citizen / green-card holder living in (or moving to) Portugal. Not tax advice — see disclaimer.
A4: HOW TO USE
A5: 1 | B5: Go to 'Inputs' and edit the yellow cells (blue text). Example values are pre-filled — overwrite them.
A6: 2 | B6: 'Summary' shows all four combinations: US method (FEIE vs Foreign Tax Credit) × PT regime (standard IRS vs IFICI/NHR 2.0) and flags the cheapest.
A7: 3 | B7: 'US_Calc' and 'PT_Calc' show every step so you can audit the math. 'Params' holds every rate, bracket and threshold (edit there if law changes).
A8: 4 | B8: Reference tabs: US_Regimes, PT_Regimes, Treaty_FTC (US–Portugal treaty & double-tax relief), Calendar, Checklist.
A9: COLOUR CODE
A10: Blue text / yellow fill | B10: Input you can change.
A11: Black text | B11: Formula.
A12: Green text | B12: Link pulled from another sheet.
A13: WHAT THE CALCULATOR MODELS
A14: US | B14: Federal only (no state tax): brackets, standard/itemized deduction, FEIE (with stacking rule), FTC limitation, LTCG 0/15/20%, NIIT, FICA / SE tax / Additional Medicare.
A15: Portugal | B15: Standard progressive IRS (cat. A employment, cat. B simplified-regime freelance, 28% autonomous capital income), solidarity surcharge, €600 personal deduction, joint-return splitting, IFICI 20% flat regime, employee/self-employed Social Security.
A16: Interaction | B16: Social security assigned to ONE country (US–PT totalization agreement). PT credit for US tax on US-source income; US FTC for PT tax on PT-source income; FEIE-excluded income gets no FTC.
A17: KEY SIMPLIFICATIONS (read these)
A18: 1 | B18: Inputs are in EUR and converted to USD with your FX rate. One earner; 'Married' = US MFJ and PT joint (quotient conjugal) with a single-earner household.
A19: 2 | B19: No dependants, credits (CTC, EITC), QBI deduction, PT expense deductions beyond the single 'other deductions' input, state taxes, real-estate, rental or pension income.
A20: 3 | B20: PT cat. B uses the simplified regime (75% coefficient) — does not model organised accounting, first-year reductions or the minimum-expense rule.
A21: 4 | B21: FTC limitation uses a single basket and gross-income source ratio; treaty re-sourcing, carryovers, and NIIT credits are NOT modelled.
A22: 5 | B22: IFICI: assumes you qualify (activity list + 5 years of non-residency) and that foreign-source income is exempt; PT-source work income taxed at flat 20%. Confirm with a Portuguese contabilista.
A23: 6 | B23: 2026 figures: US from IRS inflation adjustments (Rev. Proc. 2025-32) and OBBBA; PT from the 2026 State Budget. Both were entered from memory of published tables — VERIFY against IRS.gov / Portal das Finanças before relying on numbers. Every figure is editable on 'Params'.
A24: DISCLAIMER
B25: Educational planning tool, not legal or tax advice. Cross-border tax is fact-specific (citizenship, residency days, treaty position, entity use, PFIC, trusts). Have a US CPA/EA and a Portuguese certified accountant review before filing.

Sheet Inputs
A1: Inputs
A2: Edit yellow cells only. Example values are pre-filled (a single US citizen, salaried in Portugal) — overwrite them.
A4: Profile
A5: Tax year | C5: 2026 | D5: Fixed — parameters are for 2026
A6: Marital status | C6: Single | D6: Single = US Single / PT single. Married = US MFJ / PT joint, one earner
A7: US taxpayer (citizen / green card)? | C7: Yes | D7: No = US columns forced to zero (PT-only view)
A8: FX rate: USD per 1 EUR | C8: 1.15 | D8: ASSUMPTION — update to your rate (IRS yearly average rate for filing)
A9: Social-security country for work income | C9: Portugal | D9: US–PT totalization: pay into ONE system (certificate of coverage)
A10: Eligible for IFICI (NHR 2.0)? | C10: No | D10: Yes only if you meet the activity list + 5-yr non-residency tests
A11: Annual income (EUR)
A12: Employment salary (gross) | C12: 60000 | D12: Example value
A13: Self-employment gross revenue | C13: 0 | D13: Freelance / sole proprietor
A14: Business expenses (actual, for US net profit) | C14: 0 | D14: PT simplified regime ignores this (uses coefficient)
A15: Interest & ordinary dividends | C15: 2000
A16: Long-term gains & qualified dividends | C16: 5000 | D16: Securities held >1 year
A17: % of work income earned/sourced in Portugal | C17: 1 | D17: Remainder treated as US-source
A18: % of capital income sourced in Portugal | C18: 0 | D18: Remainder treated as US-source
A19: US itemized deductions (EUR, optional) | C19: 0 | D19: Used only if larger than standard deduction
A20: Other PT deductions to tax (EUR) | C20: 0 | D20: Health 15%, education 30%, general expenses 35% etc. — enter the credit amount
A22: Legend: blue text on yellow = input · everything else in the workbook is formula-driven.

Sheet Summary
A1: Summary — total tax burden by strategy (EUR, 2026)
A2: Combines US_Calc and PT_Calc with cross-border credits. Green row = lowest total. IFICI rows show n/a unless eligible (Inputs!C10).
A4: Shared factors
A5: Worldwide gross income (EUR) | C5: =Inputs!C12+MAX(0,Inputs!C13-Inputs!C14)+Inputs!C15+Inputs!C16 -> 67000
A6: PT-sourced income (EUR) | C6: =(Inputs!C12+MAX(0,Inputs!C13-Inputs!C14))*Inputs!C17+(Inputs!C15+Inputs!C16)*Inputs!C18 -> 60000
A7: PT-source share | C7: =IF(C5=0,0,C6/C5) -> 0.89552239
A8: US-source share | C8: =1-C7 -> 0.10447761
A9: US taxpayer flag | C9: =IF(Inputs!C7="Yes",1,0) -> 1
A11: US method | B11: PT regime | C11: US regular tax (pre-FTC) | D11: US NIIT | E11: US FTC for PT tax | F11: US income tax (net) | G11: PT income tax (pre-credit) | H11: PT credit for US tax | I11: PT income tax (net) | J11: Social security (US+PT) | K11: TOTAL tax | L11: % of gross income | M11: Best?
A12: FEIE | B12: Standard | C12: =$C$9*US_Calc!B29/Inputs!$C$8 -> 0 | D12: =$C$9*US_Calc!B30/Inputs!$C$8 -> 0 | E12: =$C$9*MIN(PT_Calc!B19*$C$7*(1-US_Calc!B35),US_Calc!B34/Inputs!$C$8) -> 0 | F12: =C12-E12+D12 -> 0 | G12: =PT_Calc!B19 -> 16797.848 | H12: =$C$9*MIN(C12*$C$8,G12*$C$8) -> 0 | I12: =G12-H12 -> 16797.848 | J12: =$C$9*US_Calc!B31/Inputs!$C$8+PT_Calc!B20 -> 6600 | K12: =F12+I12+J12 -> 23397.848 | L12: =IF($C$5=0,0,K12/$C$5) -> 0.34922161 | M12: =IF(ISNUMBER(K12),IF(K12=MIN($K$12:$K$15),"◄ lowest",""),"") -> ◄ lowest
A13: FEIE | B13: IFICI | C13: =IF(Inputs!$C$10="Yes",$C$9*US_Calc!B29/Inputs!$C$8,"n/a") -> n/a | D13: =IF(Inputs!$C$10="Yes",$C$9*US_Calc!B30/Inputs!$C$8,"n/a") -> n/a | E13: =IF(Inputs!$C$10="Yes",$C$9*MIN(PT_Calc!C19*(1-US_Calc!B35),US_Calc!B34/Inputs!$C$8),"n/a") -> n/a | F13: =IF(Inputs!$C$10="Yes",C13-E13+D13,"n/a") -> n/a | G13: =IF(Inputs!$C$10="Yes",PT_Calc!C19,"n/a") -> n/a | H13: =IF(Inputs!$C$10="Yes",0,"n/a") -> n/a | I13: =IF(Inputs!$C$10="Yes",G13-H13,"n/a") -> n/a | J13: =IF(Inputs!$C$10="Yes",$C$9*US_Calc!B31/Inputs!$C$8+PT_Calc!C20,"n/a") -> n/a | K13: =IF(Inputs!$C$10="Yes",F13+I13+J13,"n/a") -> n/a | L13: =IF(Inputs!$C$10="Yes",IF($C$5=0,0,K13/$C$5),"n/a") -> n/a | M13: =IF(ISNUMBER(K13),IF(K13=MIN($K$12:$K$15),"◄ lowest",""),"")
A14: FTC only | B14: Standard | C14: =$C$9*US_Calc!C29/Inputs!$C$8 -> 6711.7391 | D14: =$C$9*US_Calc!C30/Inputs!$C$8 -> 0 | E14: =$C$9*MIN(PT_Calc!B19*$C$7*(1-US_Calc!C35),US_Calc!C34/Inputs!$C$8) -> 6010.5127 | F14: =C14-E14+D14 -> 701.22648 | G14: =PT_Calc!B19 -> 16797.848 | H14: =$C$9*MIN(C14*$C$8,G14*$C$8) -> 701.22648 | I14: =G14-H14 -> 16096.622 | J14: =$C$9*US_Calc!C31/Inputs!$C$8+PT_Calc!B20 -> 6600 | K14: =F14+I14+J14 -> 23397.848 | L14: =IF($C$5=0,0,K14/$C$5) -> 0.34922161 | M14: =IF(ISNUMBER(K14),IF(K14=MIN($K$12:$K$15),"◄ lowest",""),"") -> ◄ lowest
A15: FTC only | B15: IFICI | C15: =IF(Inputs!$C$10="Yes",$C$9*US_Calc!C29/Inputs!$C$8,"n/a") -> n/a | D15: =IF(Inputs!$C$10="Yes",$C$9*US_Calc!C30/Inputs!$C$8,"n/a") -> n/a | E15: =IF(Inputs!$C$10="Yes",$C$9*MIN(PT_Calc!C19*(1-US_Calc!C35),US_Calc!C34/Inputs!$C$8),"n/a") -> n/a | F15: =IF(Inputs!$C$10="Yes",C15-E15+D15,"n/a") -> n/a | G15: =IF(Inputs!$C$10="Yes",PT_Calc!C19,"n/a") -> n/a | H15: =IF(Inputs!$C$10="Yes",0,"n/a") -> n/a | I15: =IF(Inputs!$C$10="Yes",G15-H15,"n/a") -> n/a | J15: =IF(Inputs!$C$10="Yes",$C$9*US_Calc!C31/Inputs!$C$8+PT_Calc!C20,"n/a") -> n/a | K15: =IF(Inputs!$C$10="Yes",F15+I15+J15,"n/a") -> n/a | L15: =IF(Inputs!$C$10="Yes",IF($C$5=0,0,K15/$C$5),"n/a") -> n/a | M15: =IF(ISNUMBER(K15),IF(K15=MIN($K$12:$K$15),"◄ lowest",""),"")
A17: Headline
A18: Lowest-tax strategy | C18: =INDEX($A$12:$A$15,MATCH(MIN($K$12:$K$15),$K$12:$K$15,0))&" + "&INDEX($B$12:$B$15,MATCH(MIN($K$12:$K$15),$K$12:$K$15,0)) -> FEIE + Standard
A19: Total tax, best strategy (EUR) | C19: =MIN($K$12:$K$15) -> 23397.848
A20: Total tax, worst strategy (EUR) | C20: =MAX($K$12:$K$15) -> 23397.848
A21: Saving from choosing best (EUR) | C21: =C20-C19 -> 0
A22: Effective rate, best strategy | C22: =IF(C5=0,0,C19/C5) -> 0.34922161
A24: Reading the table
A25: • US regular tax = bracket tax + LTCG tax. FTC offsets it for PT tax on PT-source income (never on excluded FEIE income, never against NIIT or SE tax).
A26: • PT credit = lesser of US tax on US-source income and PT tax attributable to that income (none under IFICI, where foreign income is exempt).
A27: • Social security: only one country's system applies (Inputs!C9). Employer-side contributions are not included.
A28: • FEIE vs FTC: with PT rates above US rates, FTC usually wins and builds carryovers; FEIE tends to win only when PT tax is low (e.g. IFICI at 20% on high earnings).
A29: • Compare FEIE columns carefully: electing FEIE has long-term lock-in (5-year revocation rule) and can limit credits such as the CTC/IRA contributions.

Sheet US_Calc
A1: US federal calculation (USD) — FEIE vs Foreign Tax Credit only
A2: Column B = elect FEIE (Form 2555). Column C = no FEIE, rely on FTC (Form 1116). Excludes state tax.
A4: Line | B4: FEIE elected | C4: FTC only | D4: Note
A5: FEIE elected (1 = yes) | B5: 1 | C5: 0 | D5: Hardcoded switch per column
A6: Wages | B6: =Inputs!$C$12*Inputs!$C$8 -> 69000 | C6: =Inputs!$C$12*Inputs!$C$8 -> 69000 | D6: EUR × FX
A7: Self-employment net profit | B7: =MAX(0,Inputs!$C$13-Inputs!$C$14)*Inputs!$C$8 -> 0 | C7: =MAX(0,Inputs!$C$13-Inputs!$C$14)*Inputs!$C$8 -> 0 | D7: Revenue − expenses
A8: Interest & ordinary dividends | B8: =Inputs!$C$15*Inputs!$C$8 -> 2300 | C8: =Inputs!$C$15*Inputs!$C$8 -> 2300
A9: LT gains & qualified dividends | B9: =Inputs!$C$16*Inputs!$C$8 -> 5750 | C9: =Inputs!$C$16*Inputs!$C$8 -> 5750
A10: Subject to US social security? (1/0) | B10: =IF(AND(Inputs!$C$9="US",Inputs!$C$7="Yes"),1,0) -> 0 | C10: =IF(AND(Inputs!$C$9="US",Inputs!$C$7="Yes"),1,0) -> 0 | D10: Per totalization choice
A11: SE earnings base (92.35%) | B11: =B7*Params!$B$17 -> 0 | C11: =C7*Params!$B$17 -> 0
A12: Employee FICA | B12: =B10*(MIN(B6,Params!$D$6)*Params!$B$13+B6*Params!$B$14) -> 0 | C12: =C10*(MIN(C6,Params!$D$6)*Params!$B$13+C6*Params!$B$14) -> 0 | D12: 6.2% to wage base + 1.45%
A13: Self-employment tax | B13: =B10*(MIN(B11,MAX(0,Params!$D$6-B6))*Params!$B$15+B11*Params!$B$16) -> 0 | C13: =C10*(MIN(C11,MAX(0,Params!$D$6-C6))*Params!$B$15+C11*Params!$B$16) -> 0 | D13: 12.4% to wage base + 2.9%
A14: Additional Medicare tax | B14: =B10*Params!$B$18*MAX(0,B6+B11-Params!$D$10) -> 0 | C14: =C10*Params!$B$18*MAX(0,C6+C11-Params!$D$10) -> 0 | D14: 0.9% over threshold
A15: Deduction: ½ SE tax | B15: =0.5*B13 -> 0 | C15: =0.5*C13 -> 0
A16: Foreign (PT-sourced) earned income | B16: =(B6+B7)*Inputs!$C$17 -> 69000 | C16: =(C6+C7)*Inputs!$C$17 -> 69000 | D16: Needs bona fide residence / 330-day test
A17: FEIE exclusion | B17: =B5*MIN(Params!$D$7,B16) -> 69000 | C17: =C5*MIN(Params!$D$7,C16) -> 0 | D17: Capped at limit
A18: Ordinary income (before exclusion) | B18: =B6+B7+B8 -> 71300 | C18: =C6+C7+C8 -> 71300
A19: Ordinary income after ½SE and FEIE | B19: =MAX(0,B18-B15-B17) -> 2300 | C19: =MAX(0,C18-C15-C17) -> 71300
A20: Deduction (greater of standard / itemized) | B20: =MAX(Params!$D$5,Inputs!$C$19*Inputs!$C$8) -> 16100 | C20: =MAX(Params!$D$5,Inputs!$C$19*Inputs!$C$8) -> 16100 | D20: Simplification: not reduced for FEIE-allocable items
A21: Taxable ordinary income | B21: =MAX(0,B19-B20) -> 0 | C21: =MAX(0,C19-C20) -> 55200
A22: Total taxable income | B22: =MAX(0,B19+B9-B20) -> 0 | C22: =MAX(0,C19+C9-C20) -> 60950
A23: Taxable LTCG / qualified dividends | B23: =B22-B21 -> 0 | C23: =C22-C21 -> 5750
A24: Tax on ordinary income (FEIE stacking rule) | B24: =IF(Inputs!$C$6="Single",SUMPRODUCT(((B21+B17)>Params!$A$25:$A$31)*((B21+B17)-Params!$A$25:$A$31)*Params!$C$25:$C$31),SUMPRODUCT(((B21+B17)>Params!$E$25:$E$31)*((B21+B17)-Params!$E$25:$E$31)*Params!$G$25:$G$31))-IF(Inputs!$C$6="Single",SUMPRODUCT((B17>Params!$A$25:$A$31)*(B17-Params!$A$25:$A$31)*Params!$C$25:$C$31),SUMPRODUCT((B17>Params!$E$25:$E$31)*(B17-Params!$E$25:$E$31)*Params!$G$25:$G$31)) -> 0 | C24: =IF(Inputs!$C$6="Single",SUMPRODUCT(((C21+C17)>Params!$A$25:$A$31)*((C21+C17)-Params!$A$25:$A$31)*Params!$C$25:$C$31),SUMPRODUCT(((C21+C17)>Params!$E$25:$E$31)*((C21+C17)-Params!$E$25:$E$31)*Params!$G$25:$G$31))-IF(Inputs!$C$6="Single",SUMPRODUCT((C17>Params!$A$25:$A$31)*(C17-Params!$A$25:$A$31)*Params!$C$25:$C$31),SUMPRODUCT((C17>Params!$E$25:$E$31)*(C17-Params!$E$25:$E$31)*Params!$G$25:$G$31)) -> 6856 | D24: Tax(TI+excl) − Tax(excl): excluded income pushes rates up
A25: LTCG taxed at 0% | B25: =MAX(0,MIN(B23,Params!$D$8-B21)) -> 0 | C25: =MAX(0,MIN(C23,Params!$D$8-C21)) -> 0
A26: LTCG taxed at 15% | B26: =MAX(0,MIN(B23-B25,Params!$D$9-(B21+B25))) -> 0 | C26: =MAX(0,MIN(C23-C25,Params!$D$9-(C21+C25))) -> 5750
A27: LTCG taxed at 20% | B27: =B23-B25-B26 -> 0 | C27: =C23-C25-C26 -> 0
A28: Tax on LTCG | B28: =B26*Params!$B$20+B27*Params!$B$21 -> 0 | C28: =C26*Params!$B$20+C27*Params!$B$21 -> 862.5
A29: Regular income tax (pre-credit) | B29: =B24+B28 -> 0 | C29: =C24+C28 -> 7718.5
A30: Net Investment Income Tax | B30: =Params!$B$19*MIN(B8+B9,MAX(0,B18-B15+B9-Params!$D$10)) -> 0 | C30: =Params!$B$19*MIN(C8+C9,MAX(0,C18-C15+C9-Params!$D$10)) -> 0 | D30: 3.8%; not creditable by FTC
A31: US social taxes (FICA + SE + Addl Medicare) | B31: =B12+B13+B14 -> 0 | C31: =C12+C13+C14 -> 0
A32: Foreign-source income for FTC limit | B32: =MAX(0,(B6+B7)*Inputs!$C$17-B17+(B8+B9)*Inputs!$C$18) -> 0 | C32: =MAX(0,(C6+C7)*Inputs!$C$17-C17+(C8+C9)*Inputs!$C$18) -> 69000 | D32: Net of excluded income
A33: Worldwide income for FTC limit | B33: =B19+B9 -> 8050 | C33: =C19+C9 -> 77050
A34: FTC limitation | B34: =IF(B33=0,0,B29*MIN(1,B32/B33)) -> 0 | C34: =IF(C33=0,0,C29*MIN(1,C32/C33)) -> 6912.0896 | D34: Regular tax × foreign / worldwide
A35: Share of PT-source earned income excluded | B35: =IF(B16=0,0,B17/B16) -> 1 | C35: =IF(C16=0,0,C17/C16) -> 0 | D35: PT tax on excluded income is not creditable
A36: US total before FTC (income tax + NIIT + social) | B36: =B29+B30+B31 -> 0 | C36: =C29+C30+C31 -> 7718.5 | D36: FTC applied on Summary

Sheet PT_Calc
A1: Portugal IRS calculation (EUR) — Standard vs IFICI
A2: Column B = standard progressive IRS (all income aggregated, capital at 28%). Column C = IFICI (20% flat on PT-source work income; foreign-source exempt).
A4: Line | B4: Standard IRS | C4: IFICI (20%) | D4: Note
A5: Subject to PT social security? (1/0) | B5: =IF(Inputs!$C$9="Portugal",1,0) -> 1 | C5: =IF(Inputs!$C$9="Portugal",1,0) -> 1 | D5: Per totalization choice
A6: Employment income (cat. A) | B6: =Inputs!$C$12 -> 60000 | C6: =Inputs!$C$12 -> 60000
A7: Employee Social Security (11%) | B7: =B5*Params!$B$35*B6 -> 6600 | C7: =C5*Params!$B$35*C6 -> 6600
A8: Specific deduction (greater of €4,350 / SS) | B8: =IF(B6>0,MIN(B6,MAX(Params!$B$34,B7)),0) -> 6600 | C8: =IF(C6>0,MIN(C6,MAX(Params!$B$34,C7)),0) -> 6600 | D8: Cat. A
A9: Net cat. A income | B9: =B6-B8 -> 53400 | C9: =C6-C8 -> 53400
A10: Self-employment revenue (cat. B) | B10: =Inputs!$C$13 -> 0 | C10: =Inputs!$C$13 -> 0
A11: Taxable cat. B (simplified coefficient) | B11: =B10*Params!$B$38 -> 0 | C11: =C10*Params!$B$38 -> 0 | D11: 75% × revenue
A12: Self-employed Social Security | B12: =B5*Params!$B$36*Params!$B$37*B10 -> 0 | C12: =C5*Params!$B$36*Params!$B$37*C10 -> 0 | D12: 21.4% × 70% × revenue (first-year exemption not modelled)
A13: Work income base in regime | B13: =B9+B11 -> 53400 | C13: =(C9+C11)*Inputs!$C$17 -> 53400 | D13: Standard: all work income. IFICI: PT-source share only
A14: IRS on work income | B14: =IF(Inputs!$C$6="Single",SUMPRODUCT((B13>Params!$A$49:$A$57)*(B13-Params!$A$49:$A$57)*Params!$C$49:$C$57),2*SUMPRODUCT(((B13)/2>Params!$A$49:$A$57)*((B13)/2-Params!$A$49:$A$57)*Params!$C$49:$C$57)) -> 15437.848 | C14: =C13*Params!$B$41 -> 10680 | D14: Standard: progressive (joint splits ÷2). IFICI: 20% flat
A15: Solidarity surcharge | B15: =IF(Inputs!$C$6="Single",1,2)*(Params!$B$43*MAX(0,MIN((B13/IF(Inputs!$C$6="Single",1,2)),Params!$B$44)-Params!$B$42)+Params!$B$45*MAX(0,(B13/IF(Inputs!$C$6="Single",1,2))-Params!$B$44)) -> 0 | C15: =0 -> 0 | D15: 2.5% > €80k, 5% > €250k
A16: Personal & other deductions to tax | B16: =MIN(B14,Params!$B$39*IF(Inputs!$C$6="Single",1,2)+Inputs!$C$20) -> 600 | C16: =0 -> 0 | D16: €600/taxpayer + Inputs; capped at IRS
A17: Capital income & gains base | B17: =Inputs!$C$15+Inputs!$C$16 -> 7000 | C17: =(Inputs!$C$15+Inputs!$C$16)*Inputs!$C$18 -> 0 | D17: IFICI: only PT-source taxed
A18: Autonomous tax on capital (28%) | B18: =B17*Params!$B$40 -> 1960 | C18: =C17*Params!$B$40 -> 0 | D18: Aggregation option not modelled
A19: PT income tax before foreign-tax credit | B19: =B14-B16+B15+B18 -> 16797.848 | C19: =C14-C16+C15+C18 -> 10680
A20: PT social security total | B20: =B7+B12 -> 6600 | C20: =C7+C12 -> 6600 | D20: Separate from income tax

Sheet Params
A1: Parameters — 2026 (all editable; blue = hardcoded input)
A2: US figures: IRS Rev. Proc. 2025-32 / OBBBA (P.L. 119-21). Portugal: Orçamento do Estado 2026 / CIRS. Verify before use.
A3: UNITED STATES — thresholds (USD)
A4: Item | B4: Single | C4: Married filing jointly | D4: Selected | E4: Note
A5: Standard deduction | B5: 16100 | C5: 32200 | D5: =IF(Inputs!$C$6="Single",B5,C5) -> 16100 | E5: Rev. Proc. 2025-32
A6: Social Security wage base | B6: 184500 | C6: 184500 | D6: =IF(Inputs!$C$6="Single",B6,C6) -> 184500 | E6: SSA 2026
A7: FEIE limit (per qualifying person) | B7: 132900 | C7: 132900 | D7: =IF(Inputs!$C$6="Single",B7,C7) -> 132900 | E7: Form 2555; one earner assumed
A8: LTCG 0% ceiling (taxable income) | B8: 49450 | C8: 98900 | D8: =IF(Inputs!$C$6="Single",B8,C8) -> 49450 | E8: Rev. Proc. 2025-32
A9: LTCG 15% ceiling (taxable income) | B9: 545500 | C9: 613700 | D9: =IF(Inputs!$C$6="Single",B9,C9) -> 545500 | E9: Rev. Proc. 2025-32
A10: Addl Medicare / NIIT threshold | B10: 200000 | C10: 250000 | D10: =IF(Inputs!$C$6="Single",B10,C10) -> 200000 | E10: Statutory, not indexed
A12: UNITED STATES — rates
A13: OASDI employee rate | B13: 0.062
A14: Medicare employee rate | B14: 0.0145
A15: OASDI self-employed rate | B15: 0.124
A16: Medicare self-employed rate | B16: 0.029
A17: SE earnings factor | B17: 0.9235
A18: Additional Medicare tax | B18: 0.009
A19: Net Investment Income Tax | B19: 0.038
A20: LTCG middle rate | B20: 0.15
A21: LTCG top rate | B21: 0.2
A23: UNITED STATES — ordinary income brackets 2026 (lower bound, rate, rate step)
A24: Single: from | B24: Rate | C24: Step | E24: MFJ: from | F24: Rate | G24: Step
A25: 0 | B25: 0.1 | C25: =B25 -> 0.1 | E25: 0 | F25: 0.1 | G25: =F25 -> 0.1
A26: 12400 | B26: 0.12 | C26: =B26-B25 -> 0.02 | E26: 24800 | F26: 0.12 | G26: =F26-F25 -> 0.02
A27: 50400 | B27: 0.22 | C27: =B27-B26 -> 0.1 | E27: 100800 | F27: 0.22 | G27: =F27-F26 -> 0.1
A28: 105700 | B28: 0.24 | C28: =B28-B27 -> 0.02 | E28: 211400 | F28: 0.24 | G28: =F28-F27 -> 0.02
A29: 201775 | B29: 0.32 | C29: =B29-B28 -> 0.08 | E29: 403550 | F29: 0.32 | G29: =F29-F28 -> 0.08
A30: 256225 | B30: 0.35 | C30: =B30-B29 -> 0.03 | E30: 512450 | F30: 0.35 | G30: =F30-F29 -> 0.03
A31: 640600 | B31: 0.37 | C31: =B31-B30 -> 0.02 | E31: 768700 | F31: 0.37 | G31: =F31-F30 -> 0.02
A33: PORTUGAL — parameters (EUR)
A34: Specific deduction, cat. A (min.) | B34: 4350 | E34: CIRS art. 25
A35: Employee Social Security rate | B35: 0.11 | E35: Segurança Social
A36: Self-employed SS rate | B36: 0.214 | E36: Código Contributivo
A37: SS relevant-income share (services) | B37: 0.7 | E37: 70% of quarterly revenue
A38: Simplified-regime coefficient (services) | B38: 0.75 | E38: CIRS art. 31; 0.35 for some activities
A39: Personal deduction per taxpayer (dedução à coleta) | B39: 600 | E39: CIRS art. 78-A
A40: Autonomous rate: interest, dividends, securities gains | B40: 0.28 | E40: CIRS art. 72
A41: IFICI flat rate | B41: 0.2 | E41: EBF art. 58-A
A42: Solidarity surcharge threshold 1 | B42: 80000 | E42: CIRS art. 68-A
A43: Solidarity rate 1 | B43: 0.025
...

Sheet US_Regimes
A1: United States — regimes, laws & traps for expats
A2: Planning reference. Verify current-year figures at IRS.gov.
A4: Topic | B4: Rule | C4: Planning notes | D4: Form / source
A5: Worldwide taxation | B5: US citizens & green-card holders are taxed on worldwide income wherever they live, and must file even if tax owed is zero. | C5: Citizenship-based taxation; treaty 'saving clause' keeps US right to tax own citizens. | D5: Form 1040
A6: Filing status / brackets | B6: Single, MFJ, MFS, HoH, QSS. 7 brackets 10%–37% (see Params). | C6: OBBBA (July 2025) made TCJA rates permanent. 2026 std deduction $16,100 single / $32,200 MFJ. | D6: Rev. Proc. 2025-32
A7: Foreign Earned Income Exclusion (FEIE) | B7: Exclude foreign earned income up to $132,900 (2026) if tax home abroad and Bona Fide Residence or 330-day Physical Presence test met. | C7: Earned income only (not dividends/gains). Stacking rule taxes remaining income at higher rates. No FTC on excluded income. Revocation locks out re-election ~5 years. Self-employment tax still due unless totalization applies. | D7: Form 2555
A8: Foreign housing exclusion / deduction | B8: Excess housing costs above 16% of FEIE base can be excluded/deducted, capped by location. | C8: Portugal limit per IRS table — check annual notice. | D8: Form 2555
A9: Foreign Tax Credit (FTC) | B9: Dollar-for-dollar credit for foreign income taxes on foreign-source income, limited to US tax on that income, by basket (general, passive). | C9: 1-yr carryback, 10-yr carryforward. Often best when PT tax ≥ US tax. Needed to avoid double tax on PT-source dividends, gains. | D9: Form 1116
A10: Social security: FICA / SE tax | B10: Employee 7.65%; self-employed 15.3% on 92.35% of net profit (OASDI wage base $184,500 for 2026). Additional Medicare 0.9% above $200k/$250k. | C10: US–PT totalization agreement (in force 1989): pay in ONE country. PT-employed → PT SS; US employer sending you abroad → certificate of coverage from SSA (up to 5 yrs). | D10: Form 1040 Sch SE; SSA certificate
A11: Net Investment Income Tax | B11: 3.8% on lesser of NII or MAGI above $200k/$250k. | C11: Not reduced by FTC (treaty credit position debated). | D11: Form 8960
A12: Capital gains & qualified dividends | B12: 0% / 15% / 20% on long-term gains; ordinary rates for short-term. | C12: Primary-home exclusion $250k/$500k (§121). PT also exempts main-home gains if reinvested. | D12: Form 8949, Sch D
A13: QBI deduction (§199A) | B13: Up to 20% deduction for pass-through business income (made permanent by OBBBA). | C13: Applies to US trade or business income; foreign-source income generally excluded. | D13: Form 8995
A14: PFIC rules | B14: Non-US funds/ETFs (including most Portuguese funds) are Passive Foreign Investment Companies — punitive tax and heavy reporting. | C14: Buy US-domiciled ETFs/funds where possible; consider QEF/MTM elections. Common expat trap. | D14: Form 8621
A15: FBAR | B15: Report foreign accounts if aggregate balance > $10,000 at any time in the year. | C15: Due Apr 15, automatic extension to Oct 15. Penalties severe, even for non-wilful. | D15: FinCEN 114
... A21: Expatriation | B21: Covered expatriates face exit tax (§877A) on deemed sale of assets. | C21: Test: net worth ≥ $2M, avg tax liability > threshold, or non-compliance in 5 years. | D21: Form 8854
A22: Deadlines abroad | B22: Automatic 2-month extension to Jun 15 for taxpayers abroad; Form 4868 to Oct 15. Interest still runs from Apr 15. | D22: —
A23: Streamlined procedures | B23: Catch up on missed filings with reduced/no penalties if non-wilful. | C23: Streamlined Foreign Offshore Procedures: 3 years returns + 6 years FBARs; no penalty. | D23: Form 14653
A24: State tax | B24: Some states keep claiming residents who move abroad (CA, NY, VA, SC, NM etc.). | C24: Break domicile cleanly: driver's licence, voter registration, property, banking. | D24: State rules

Sheet PT_Regimes
A1: Portugal — regimes, laws & traps
A2: Planning reference. Tax rules change yearly — confirm with the State Budget and a certified accountant (contabilista certificado).
A4: Topic | B4: Rule | C4: Planning notes | D4: Source
A5: Tax residency | B5: Resident if >183 days in PT in any 12-month period or you hold a habitual dwelling on 31 Dec that suggests intent to keep it. | C5: Residents taxed on worldwide income; non-residents on PT-source only (25% flat on most income). | D5: CIRS art. 16
A6: Categories of income | B6: A employment · B business/professional · E capital · F rental · G capital gains · H pensions. | C6: Each category has own deductions and sometimes own rates. | D6: CIRS art. 1–3
A7: Progressive IRS rates | B7: 9 brackets 12.5%–48% on mainland (see Params, 2026). | C7: Joint filing: quotient conjugal — income halved, tax doubled. | D7: CIRS art. 68
A8: Specific deduction (cat. A) | B8: €4,350 or SS contributions if higher. | D8: CIRS art. 25
A9: Solidarity surcharge | B9: 2.5% on taxable income €80k–€250k; 5% above €250k. | D9: CIRS art. 68-A
A10: Personal deductions (dedução à coleta) | B10: €600/taxpayer; health 15% (cap €1,000); education 30% (cap €800); general expenses 35% (cap €250); housing, ERPI, VAT-receipt (e-fatura) categories. | C10: Deductions to tax, not income. | D10: CIRS art. 78-A ff.
A11: Freelancers — simplified regime | B11: Taxable income = 75% of professional-services revenue (35% for many other activities). Organised accounting optional/required above €200k. | C11: Minimum deduction rule: expenses + SS must reach 15% of revenue or you deduct the shortfall. First-year 50% / second-year 25% reduction. | D11: CIRS art. 28, 31
A12: Autonomous taxation 28% | B12: Interest, dividends and securities gains taxed at 28% flat (option to aggregate). | C12: US-PT treaty caps source withholding at 15% (dividends) / 10% (interest). Crypto gains < 365 days taxed 28%; ≥365 days exempt (check latest budget). | D12: CIRS art. 72
A13: Real estate gains | B13: 50% of gain taxed at progressive rates; exclusion for main home if proceeds reinvested in PT/EU within 36 months. | C13: Inflation adjustment on cost for holdings >24 months. | D13: CIRS art. 10
A14: Rental income (cat. F) | B14: 28% autonomous (reduced rates for long leases) or aggregate; expenses deductible. | C14: Non-residents 25%. Alojamento Local (short-term) regime: 35% coefficient. | D14: CIRS art. 72
A15: NHR regime (legacy) | B15: Closed to new entrants after 31 Mar 2024. Those already registered keep 10-year benefits: 20% flat on PT-source high-value work; foreign income largely exempt; pensions had 10%. | C15: Transitional rule: eligible if you had a lease/purchase or work contract by 31 Dec 2023. | D15: EBF art. 58-A (old)
A16: IFICI / 'NHR 2.0' | B16: 10-year regime: 20% flat on PT-source employment/self-employment in eligible activities (researchers, tech, startups, qualifying companies, etc.). Foreign-source income of cats. A, B, E, F, G generally exempt, subject to conditions. | C16: Not tax resident in PT in prior 5 years. Register at Finanças by Jan 15 of year after arriving. Pensions are NOT covered. Check US citizens' treaty position. | D16: Law 20/2024; EBF art. 58-A
A17: IRS Jovem | B17: Age ≤ 35: exemption on salaries — 100% yr 1 falling to 25% yr 10 (post-2025 scheme; caps). | C17: Cannot be combined with IFICI. | D17: CIRS art. 12-B
A18: Social Security | B18: Employee 11%, employer 23.75%. Self-employed 21.4% on 70% of revenue (services), 12-month first-year exemption. | C18: Exempt if covered by US system under totalization agreement. | D18: Código Contributivo
A19: Corporate (IRC) | B19: Standard rate 20% in 2025, falling ~1 pt/yr to 17% by 2028; reduced SME rate on first €50k; municipal surcharge up to 1.5% + state surcharge on large profits. | C19: Verify yearly. Dividends from Lda to US person: PT 28% withholding, treaty 15% — plus US PFIC/GILTI issues. | D19: CIRC
A20: VAT (IVA) | B20: Mainland 23% / 13% / 6%; Madeira & Azores lower. Exemption below ~€15k turnover (small-business regime). | C20: Registered via Atividade Aberta; quarterly or monthly returns. | D20: CIVA
A21: Property taxes | B21: IMI 0.3%–0.45% on urban property annually; AIMI on holdings > €600k per owner (0.7%–1.5%); IMT on purchase (up to 8%); stamp duty 0.8% on purchase. | C21: No wealth, inheritance (to family) or gift tax among close relatives. | D21: CIMI / CIMT / CIS
A22: Wealth / inheritance | B22: No general wealth tax. Stamp duty 10% on inheritance to non-spouse/descendants/ascendants. | D22: CIS
A23: Filing | B23: Modelo 3 annually, Apr 1–Jun 30; payment by Sep 30. Anexo J for foreign income (US wages, dividends, gains). Joint or separate. | C23: Foreign income must be declared even if exempt; exempt income still enters rate calculation (progressão). | D23: Portal das Finanças
A24: Foreign accounts | B24: Disclose foreign bank accounts on Modelo 3 (Anexo J, Q.14). | C24: Required alongside US FBAR/8938. | D24: Anexo J

Sheet Treaty_FTC
A1: US–Portugal treaty & double-tax relief
A2: Summary of main treaty mechanics; always read the treaty text and the saving clause exceptions.
A4: Topic | B4: Treaty position | C4: Planning implication | D4: Article
A5: Treaty | B5: US–Portugal Income Tax Convention, signed 1994, in force 1996. | C5: Article 4 (residence), 10–12 (investment income), 15–19 (employment, artists, pensions, gov't service), 24 (relief), 'savings clause'.
A6: Residence tie-breaker (Art. 4) | B6: If resident of both: 1) permanent home, 2) centre of vital interests, 3) habitual abode, 4) nationality, 5) mutual agreement. | C6: US citizen + PT resident = dual-resident → usually PT under test 1–2 for treaty purposes, but US still taxes citizens via saving clause. | D6: Art. 4
A7: Dividends (Art. 10) | B7: Source-country cap: 5% (company holding ≥25%) / 15% otherwise. | C7: Resident country taxes in full with credit for source tax. | D7: Art. 10
A8: Interest (Art. 11) | B8: Cap 10% at source. | D8: Art. 11
A9: Royalties (Art. 12) | B9: Cap 10% at source. | D9: Art. 12
A10: Capital gains (Art. 13) | B10: Real estate: taxed where situated. Shares: residence state (with exceptions). | C10: PT 28% on securities gains; US 15%/20% with FTC. | D10: Art. 13
A11: Employment (Art. 15) | B11: Taxed where work is performed; 183-day exception for short secondments. | C11: Remote work for a US employer from PT is PT-source for PT purposes. | D11: Art. 15
A12: Pensions (Art. 18) | B12: Private pensions taxable only in residence state. Social Security benefits taxable only in paying state. | C12: Treaty benefit for US Social Security benefits — but saving clause for US citizens; check current IRS position. | D12: Art. 18
A13: Relief from double taxation (Art. 24) | B13: Portugal grants credit for US tax on US-source income; US grants FTC for PT tax. Credit limited to tax on that income. | C13: US citizens: US credit generally for PT tax on PT-source income; PT re-sourcing rules in Art. 24 may allow credits for US tax on US-source dividends. | D13: Art. 24
A14: Saving clause | B14: US reserves right to tax its citizens/residents as if the treaty had not come into effect (with exceptions). | C14: Why FTC/FEIE planning matters even with a treaty. | D14: Art. 1
A15: Totalization agreement | B15: Social Security: in force 1989. Pay in one country only; employee/self-employed coverage rules; certificate of coverage. | C15: Self-employed: coverage follows country of residence; employee: country of work, with detached-worker exception. | D15: SSA/Segurança Social
A16: Mutual agreement procedure | B16: Taxpayer may request competent-authority assistance if taxed contrary to treaty. | C16: Rare, slow; consider only for material double-tax disputes. | D16: Art. 25

Sheet Calendar
A1: Compliance calendar — US & Portugal
A2: Dates are typical; confirm yearly. Weekend/holiday shifts apply.
A4: Date | B4: Country | C4: Obligation | D4: Form / system | E4: Notes
A5: Jan 15 | B5: US | C5: Q4 estimated tax payment (Form 1040-ES) for prior year | D5: Estimated taxes | E5: If income not subject to withholding
A6: Jan 15 | B6: PT | C6: IFICI/NHR registration deadline (year after arrival) | D6: Finanças portal | E6: Verify exact current rule
A7: Apr 1 – Jun 30 | B7: PT | C7: IRS Modelo 3 filing window (+ Anexo J for foreign income) | D7: Modelo 3 | E7: Payment due by Sep 30 (or instalments)
A8: Apr 15 | B8: US | C8: Form 1040 due; FBAR (FinCEN 114) due | D8: Form 1040, FinCEN 114 | E8: Residents abroad get automatic extension to Jun 15 (tax) / Oct 15 (FBAR)
A9: Jun 15 | B9: US | C9: Return due date for taxpayers abroad (interest accrues from Apr 15) | D9: Form 1040 | E9: Q2 estimated payment also due
A10: Sep 30 | B10: PT | C10: IRS payment deadline (Modelo 3 balance) | D10: Portal das Finanças
A11: Oct 15 | B11: US | C11: Extended return due date (Form 4868) and FBAR extension end | D11: Form 4868
A12: Quarterly (Jan/Apr/Jul/Oct) | B12: PT | C12: Self-employed Social Security quarterly declaration + VAT returns | D12: Segurança Social / IVA | E12: Quarterly regime if turnover < €650k
A13: Apr / Jul / Nov | B13: PT | C13: IMI (property tax) instalments | D13: Finanças | E13: Single payment possible if under €100
A14: Sep | B14: PT | C14: AIMI (additional property tax) payment | D14: Finanças | E14: If holdings > €600k
A15: Dec 31 | B15: Both | C15: Year-end tax planning: harvest gains/losses, FEIE 330-day count, tax-residence day count | D15: —
A16: Anytime | B16: Both | C16: Obtain NIF, Social Security number, certificate of coverage, open PT bank account (note FBAR) | D16: —

Sheet Checklist
A1: Planning checklist
A2: Update status in column E.
A4: Task | B4: Country | C4: Priority | D4: Deadline | E4: Status | F4: Notes
A5: Confirm tax residency in PT and US (day count, habitual dwelling) | B5: Both | C5: High | D5: Before first filing | E5: Not started | F5: Apply treaty tie-breaker where dual-resident
A6: Obtain NIF, NISS, open PT bank account | B6: PT | C6: High | D6: On arrival | E6: Not started | F6: Report accounts on FBAR/8938 and Anexo J
A7: Decide FEIE vs FTC (run Summary) | B7: US | C7: High | D7: Before filing | E7: Not started | F7: FTC builds carryover credits; FEIE locks in
A8: Evaluate IFICI eligibility and register | B8: PT | C8: High | D8: Jan 15 following arrival | E8: Not started | F8: Activity list + 5 years non-resident
A9: Social-security coverage: obtain certificate of coverage | B9: Both | C9: High | D9: Before starting work | E9: Not started | F9: Avoid double contributions
A10: Check investments for PFIC exposure | B10: US | C10: High | D10: Annually | E10: Not started | F10: Replace non-US ETFs with US-domiciled where possible
A11: File FBAR and Form 8938 where thresholds met | B11: US | C11: High | D11: Apr 15 / Oct 15 | E11: Not started
A12: Check retirement accounts (Roth / IRA) for PT tax treatment | B12: Both | C12: Medium | D12: Before contributions/distributions | E12: Not started | F12: PT does not give Roth exemption
A13: Review self-employment structure (sole trader vs Lda) | B13: Both | C13: Medium | D13: Before starting | E13: Not started | F13: Lda raises GILTI/5471 issues for US owners
A14: Review US state domicile exit | B14: US | C14: Medium | D14: On departure | E14: Not started
A15: Check treaty withholding forms (W-8/W-9, PT Modelo 21-RFI) | B15: Both | C15: Medium | D15: Annually | E15: Not started
A16: Estate planning: US/PT wills; PT forced heirship (Reg. EU 650/2012 choice of law) | B16: Both | C16: Low | D16: Annually | E16: Not started | F16: Choose law of nationality in will
A17: Hire US CPA/EA + PT contabilista certificado | B17: Both | C17: High | D17: Before filing | E17: Not started | F17: Cross-border specialists
